Workbook
Name NativeTimeline_date: #N/A
Name Slicer_age_group: #N/A
Name Slicer_gender: #N/A
Name Slicer_product_category: #N/A

Sheet Dashboard
B2: RETAIL SALES ANALYTICS DASHBOARD
C5: 💰 Total Sales | F5: 🛒 Total Orders | I5: 🔖 Unit Sold | L5: 💵 Avg Sales Value | O5: 👤 Avg Age
C6: =GETPIVOTDATA("Total Sales",'Pivot_table & Chart'!$C$61) -> 463570 | F6: =GETPIVOTDATA("Total Orders",'Pivot_table & Chart'!$C$61) -> 1000 | I6: =GETPIVOTDATA("Unit Sold",'Pivot_table & Chart'!F62) -> 2560 | L6: =GETPIVOTDATA("Average sales value",'Pivot_table & Chart'!G62) -> 463.57 | O6: =GETPIVOTDATA("Average age",'Pivot_table & Chart'!E62) -> 41.164

Sheet Statistics_summary_table
B2: Statistics Summary Table
B3: 1 | C3: Mean Sales | D3: =AVERAGE(retail_sales_table[[#All],[total_amount]]) -> 463.57
B4: 2 | C4: Median Sales | D4: =MEDIAN(retail_sales_table[[#All],[total_amount]]) -> 150
B5: 3 | C5: Mode | D5: =_xlfn.MODE.SNGL(retail_sales_table[[#All],[total_amount]]) -> 50
B6: 4 | C6: Variance | D6: =_xlfn.VAR.S(retail_sales_table[[#All],[total_amount]]) -> 327915.02
B7: 5 | C7: Standard Deviation | D7: =_xlfn.STDEV.S(retail_sales_table[[#All],[total_amount]]) -> 572.63865
B8: 6 | C8: Minimum Sale | D8: =MIN(retail_sales_table[[#All],[total_amount]]) -> 25
B9: 7 | C9: Maximum Sale | D9: =MAX(retail_sales_table[[#All],[total_amount]]) -> 3000
B10: 8 | C10: Range | D10: =MAX(retail_sales_table[[#All],[total_amount]])-MIN(retail_sales_table[[#All],[total_amount]]) -> 2975
B11: 9 | C11: Q1 | D11: =_xlfn.QUARTILE.INC(retail_sales_table[[#All],[total_amount]],1) -> 60
B12: 10 | C12: Q2 | D12: =_xlfn.QUARTILE.INC(retail_sales_table[[#All],[total_amount]],2) -> 150
B13: 11 | C13: Q3 | D13: =_xlfn.QUARTILE.INC(retail_sales_table[[#All],[total_amount]],3) -> 900
B14: 12 | C14: IQR | D14: =_xlfn.QUARTILE.INC(retail_sales_table[[#All],[total_amount]],3)-_xlfn.QUARTILE.INC(retail_sales_table[[#All],[total_amount]],1) -> 840

Sheet T-TEST
A1: Male_Sales | B1: Female_Sales
A2: 150 | B2: 1000 | D2: P-value (T-Test)
A3: 30 | B3: 30 | D3: =_xlfn.T.TEST(A1:A101, B1:B101, 2,3) -> 0.51339762
A4: 500 | B4: 200 | D4: Since p = 0.5134 >0.005, There is no significant diffrence between Male and Female average sales.
A5: 100 | B5: 2000
A6: 50 | B6: 100
A7: 100 | B7: 50
A8: 600 | B8: 50
A9: 100 | B9: 500
A10: 75 | B10: 120
A11: 1500 | B11: 300
A12: 120 | B12: 50
A13: 1500 | B13: 1000
A14: 900 | B14: 50
A15: 100 | B15: 500
A16: 1200 | B16: 30
... A478: 120 | B478: 300
B479: 900
B480: 150
B481: 500
B482: 75
B483: 900
B484: 1500
B485: 75
B486: 100
B487: 30
B488: 200
B489: 500
B490: 200
... B524: 150

Sheet Pivot_table & Chart
A3: Row Labels | B3: Sum of total_amount
A4: January | B4: 35740
A5: February | B5: 49040
A6: March | B6: 30340
A7: April | B7: 39645
A8: May | B8: 51295
A9: June | B9: 38055
A10: July | B10: 36240
A11: August | B11: 46045
A12: September | B12: 37190
A13: October | B13: 38320
A14: November | B14: 26895
A15: December | B15: 34765
A16: Grand Total | B16: 463570
A20: Row Labels | B20: Sum of total_amount
A21: Beauty | B21: 147315
A22: Clothing | B22: 158800
A23: Electronics | B23: 157455
A24: Grand Total | B24: 463570
A28: Row Labels | B28: Sum of total_amount
A29: Female | B29: 247125
A30: Male | B30: 216445
A31: Grand Total | B31: 463570
A35: Row Labels | B35: Sum of total_amount
A36: 18-25 | B36: 91045
A37: 26-35 | B37: 90250
A38: 36-45 | B38: 89005
A39: 46+ | B39: 193270
A40: Grand Total | B40: 463570
A44: Row Labels | B44: Sum of total_amount
A45: CUST018 | B45: 6000
A46: CUST026 | B46: 7000
A47: CUST029 | B47: 9650
A48: CUST049 | B48: 5900
A49: CUST063 | B49: 7620
A50: CUST073 | B50: 4825
A51: CUST076 | B51: 6695
A52: CUST108 | B52: 5710
A53: CUST113 | B53: 9485
A54: CUST139 | B54: 7075
...

Sheet Clean_dataset
A1: transaction_id | B1: date | C1: customer_id | D1: gender | E1: age | F1: product_category | G1: quantity | H1: price_per_unit | I1: total_amount | J1: month | K1: month_number | L1: year | M1: age_group
A2: 1 | B2: 45658 | C2: CUST001 | D2: Male | E2: 34 | F2: Beauty | G2: 3 | H2: 50 | I2: =G2*H2 -> 150 | J2: =TEXT([1]retail_sales_cleaned_dataset!B2,"mmmm") -> January | K2: =MONTH([1]retail_sales_cleaned_dataset!B2) -> 1 | L2: =YEAR([1]retail_sales_cleaned_dataset!B2) -> 2025 | M2: =IF(E2<=25,"18-25",IF(E2<=35,"26-35",IF(E2<=45,"36-45","46+"))) -> 26-35
A3: 2 | B3: 45658 | C3: CUST002 | D3: Female | E3: 26 | F3: Clothing | G3: 2 | H3: 500 | I3: =G3*H3 -> 1000 | J3: =TEXT([1]retail_sales_cleaned_dataset!B3,"mmmm") -> January | K3: =MONTH([1]retail_sales_cleaned_dataset!B3) -> 1 | L3: =YEAR([1]retail_sales_cleaned_dataset!B3) -> 2025 | M3: =IF(E3<=25,"18-25",IF(E3<=35,"26-35",IF(E3<=45,"36-45","46+"))) -> 26-35
A4: 3 | B4: 45658 | C4: CUST003 | D4: Male | E4: 50 | F4: Electronics | G4: 1 | H4: 30 | I4: =G4*H4 -> 30 | J4: =TEXT([1]retail_sales_cleaned_dataset!B4,"mmmm") -> January | K4: =MONTH([1]retail_sales_cleaned_dataset!B4) -> 1 | L4: =YEAR([1]retail_sales_cleaned_dataset!B4) -> 2025 | M4: =IF(E4<=25,"18-25",IF(E4<=35,"26-35",IF(E4<=45,"36-45","46+"))) -> 46+
A5: 4 | B5: 45659 | C5: CUST004 | D5: Male | E5: 37 | F5: Clothing | G5: 1 | H5: 500 | I5: =G5*H5 -> 500 | J5: =TEXT([1]retail_sales_cleaned_dataset!B5,"mmmm") -> January | K5: =MONTH([1]retail_sales_cleaned_dataset!B5) -> 1 | L5: =YEAR([1]retail_sales_cleaned_dataset!B5) -> 2025 | M5: =IF(E5<=25,"18-25",IF(E5<=35,"26-35",IF(E5<=45,"36-45","46+"))) -> 36-45
A6: 5 | B6: 45659 | C6: CUST005 | D6: Male | E6: 30 | F6: Beauty | G6: 2 | H6: 50 | I6: =G6*H6 -> 100 | J6: =TEXT([1]retail_sales_cleaned_dataset!B6,"mmmm") -> January | K6: =MONTH([1]retail_sales_cleaned_dataset!B6) -> 1 | L6: =YEAR([1]retail_sales_cleaned_dataset!B6) -> 2025 | M6: =IF(E6<=25,"18-25",IF(E6<=35,"26-35",IF(E6<=45,"36-45","46+"))) -> 26-35
A7: 6 | B7: 45659 | C7: CUST006 | D7: Female | E7: 45 | F7: Beauty | G7: 1 | H7: 30 | I7: =G7*H7 -> 30 | J7: =TEXT([1]retail_sales_cleaned_dataset!B7,"mmmm") -> January | K7: =MONTH([1]retail_sales_cleaned_dataset!B7) -> 1 | L7: =YEAR([1]retail_sales_cleaned_dataset!B7) -> 2025 | M7: =IF(E7<=25,"18-25",IF(E7<=35,"26-35",IF(E7<=45,"36-45","46+"))) -> 36-45
A8: 7 | B8: 45659 | C8: CUST007 | D8: Male | E8: 46 | F8: Clothing | G8: 2 | H8: 25 | I8: =G8*H8 -> 50 | J8: =TEXT([1]retail_sales_cleaned_dataset!B8,"mmmm") -> January | K8: =MONTH([1]retail_sales_cleaned_dataset!B8) -> 1 | L8: =YEAR([1]retail_sales_cleaned_dataset!B8) -> 2025 | M8: =IF(E8<=25,"18-25",IF(E8<=35,"26-35",IF(E8<=45,"36-45","46+"))) -> 46+
A9: 8 | B9: 45660 | C9: CUST008 | D9: Male | E9: 30 | F9: Electronics | G9: 4 | H9: 25 | I9: =G9*H9 -> 100 | J9: =TEXT([1]retail_sales_cleaned_dataset!B9,"mmmm") -> January | K9: =MONTH([1]retail_sales_cleaned_dataset!B9) -> 1 | L9: =YEAR([1]retail_sales_cleaned_dataset!B9) -> 2025 | M9: =IF(E9<=25,"18-25",IF(E9<=35,"26-35",IF(E9<=45,"36-45","46+"))) -> 26-35
A10: 9 | B10: 45661 | C10: CUST009 | D10: Male | E10: 63 | F10: Electronics | G10: 2 | H10: 300 | I10: =G10*H10 -> 600 | J10: =TEXT([1]retail_sales_cleaned_dataset!B10,"mmmm") -> January | K10: =MONTH([1]retail_sales_cleaned_dataset!B10) -> 1 | L10: =YEAR([1]retail_sales_cleaned_dataset!B10) -> 2025 | M10: =IF(E10<=25,"18-25",IF(E10<=35,"26-35",IF(E10<=45,"36-45","46+"))) -> 46+
A11: 10 | B11: 45661 | C11: CUST010 | D11: Female | E11: 52 | F11: Clothing | G11: 4 | H11: 50 | I11: =G11*H11 -> 200 | J11: =TEXT([1]retail_sales_cleaned_dataset!B11,"mmmm") -> January | K11: =MONTH([1]retail_sales_cleaned_dataset!B11) -> 1 | L11: =YEAR([1]retail_sales_cleaned_dataset!B11) -> 2025 | M11: =IF(E11<=25,"18-25",IF(E11<=35,"26-35",IF(E11<=45,"36-45","46+"))) -> 46+
A12: 11 | B12: 45661 | C12: CUST011 | D12: Male | E12: 23 | F12: Clothing | G12: 2 | H12: 50 | I12: =G12*H12 -> 100 | J12: =TEXT([1]retail_sales_cleaned_dataset!B12,"mmmm") -> January | K12: =MONTH([1]retail_sales_cleaned_dataset!B12) -> 1 | L12: =YEAR([1]retail_sales_cleaned_dataset!B12) -> 2025 | M12: =IF(E12<=25,"18-25",IF(E12<=35,"26-35",IF(E12<=45,"36-45","46+"))) -> 18-25
A13: 12 | B13: 45662 | C13: CUST009 | D13: Male | E13: 35 | F13: Beauty | G13: 3 | H13: 25 | I13: =G13*H13 -> 75 | J13: =TEXT([1]retail_sales_cleaned_dataset!B13,"mmmm") -> January | K13: =MONTH([1]retail_sales_cleaned_dataset!B13) -> 1 | L13: =YEAR([1]retail_sales_cleaned_dataset!B13) -> 2025 | M13: =IF(E13<=25,"18-25",IF(E13<=35,"26-35",IF(E13<=45,"36-45","46+"))) -> 26-35
... A1001: 1000 | B1001: 46022 | C1001: CUST703 | D1001: Male | E1001: 34 | F1001: Electronics | G1001: 4 | H1001: 30 | I1001: =G1001*H1001 -> 120 | J1001: =TEXT([1]retail_sales_cleaned_dataset!B1001,"mmmm") -> December | K1001: =MONTH([1]retail_sales_cleaned_dataset!B1001) -> 12 | L1001: =YEAR([1]retail_sales_cleaned_dataset!B1001) -> 2025 | M1001: =IF(E1001<=25,"18-25",IF(E1001<=35,"26-35",IF(E1001<=45,"36-45","46+"))) -> 26-35

Sheet retail_sales_dataset
A1: Transaction ID | B1: date | C1: Customer ID | D1: Gender | E1: Age | F1: Product Category | G1: Quantity | H1: Price per Unit | I1: Total Amount
A2: 1 | B2: 45658 | C2: CUST001 | D2: Male | E2: 34 | F2: Beauty | G2: 3 | H2: 50 | I2: 150
A3: 2 | B3: 45658 | C3: CUST002 | D3: Female | E3: 26 | F3: Clothing | G3: 2 | H3: 500 | I3: 1000
A4: 3 | B4: 45658 | C4: CUST003 | D4: Male | E4: 50 | F4: Electronics | G4: 1 | H4: 30 | I4: 30
A5: 4 | B5: 45659 | C5: CUST004 | D5: Male | E5: 37 | F5: Clothing | G5: 1 | H5: 500 | I5: 500
A6: 5 | B6: 45659 | C6: CUST005 | D6: Male | E6: 30 | F6: Beauty | G6: 2 | H6: 50 | I6: 100
A7: 6 | B7: 45659 | C7: CUST006 | D7: Female | E7: 45 | F7: Beauty | G7: 1 | H7: 30 | I7: 30
A8: 7 | B8: 45659 | C8: CUST007 | D8: Male | E8: 46 | F8: Clothing | G8: 2 | H8: 25 | I8: 50
A9: 8 | B9: 45660 | C9: CUST008 | D9: Male | E9: 30 | F9: Electronics | G9: 4 | H9: 25 | I9: 100
A10: 9 | B10: 45661 | C10: CUST009 | D10: Male | E10: 63 | F10: Electronics | G10: 2 | H10: 300 | I10: 600
A11: 10 | B11: 45661 | C11: CUST010 | D11: Female | E11: 52 | F11: Clothing | G11: 4 | H11: 50 | I11: 200
A12: 11 | B12: 45661 | C12: CUST011 | D12: Male | E12: 23 | F12: Clothing | G12: 2 | H12: 50 | I12: 100
A13: 12 | B13: 45662 | C13: CUST012 | D13: Male | E13: 35 | F13: Beauty | G13: 3 | H13: 25 | I13: 75
... A1001: 1000 | B1001: 46022 | C1001: CUST703 | D1001: Male | E1001: 34 | F1001: Electronics | G1001: 4 | H1001: 30 | I1001: 120
